Workbook

Sheet conversion factor
C2: From article: Diving into the Depths: Uncovering Microplastics in Norwegian Coastal Sediment Cores
C3: Average Wet Density [g/cm^3] | D3: Water content [%] | E3: porosity | F3: Dry bulk density [g/cm^3]
C4: 1.5896923 | D4: 59.81164 | E4: 0.5981164 | F4: 0.99157593
B6: Dry Matter [%] | C6: Dry bulk density | D6: Average Wet Density [kg/Litre] | E6: Factor
B7: =1-D4/100 -> 0.4018836 | C7: =F4 -> 0.99157593 | D7: 1.5896923 | E7: =B7*D7 -> 0.63887127
F16: =F4/D7 -> 0.62375336

Sheet Sheet1
A1: Study | B1: Location | C1: Sample type | D1: Water depth at location | E1: Sampling Depth | F1: Total Value | G1: unit | H1: Plastic type | I1: Transformed depth | J1: unit depth | K1: Mp count [0-100μm[ | L1: Mp count [100μm-500μm[ | M1: Mp count [500μm-5mm[ | N1: Transformed data (MP particles pr. Litre) | O1: Comment | P1: Column1
A2: Trapping of Microplastics in Halocline and Turbidity Layers of the Semi-enclosed Baltic Sea | B2: TFO5 | C2: W | D2: =E4 -> 12 | E2: 0 | F2: 7.62 | G2: items L-1 | I2: 0 | J2: m | K2: =0.18*N2 -> 1.3716 | L2: =0.4*N2 -> 3.048 | M2: =0.42*N2 -> 3.2004 | N2: 7.62 | O2: =SUM(K2:M2) -> 7.62
A3: Trapping of Microplastics in Halocline and Turbidity Layers of the Semi-enclosed Baltic Sea | B3: TFO5 | C3: W | D3: 12 | E3: 6 | F3: 7.01 | G3: items L-1 | I3: 6 | J3: m | K3: =0.18*N3 -> 1.2618 | L3: =0.4*N3 -> 2.804 | M3: =0.42*N3 -> 2.9442 | N3: 7.01 | O3: =SUM(K3:M3) -> 7.01
A4: Trapping of Microplastics in Halocline and Turbidity Layers of the Semi-enclosed Baltic Sea | B4: TFO5 | C4: B | D4: 12 | E4: 12 | F4: 8.8 | G4: items L-1 | I4: 12 | J4: m | K4: =0.18*N4 -> 1.584 | L4: =0.4*N4 -> 3.52 | M4: =0.42*N4 -> 3.696 | N4: 8.8 | O4: =SUM(K4:M4) -> 8.8
A5: Trapping of Microplastics in Halocline and Turbidity Layers of the Semi-enclosed Baltic Sea | B5: TFO5 | C5: S | D5: 12 | E5: 2 - 7cm | F5: 0.5 | G5: items L-1 | I5: =4.5/100 -> 0.045 | J5: m | K5: =0.35*N5 -> 0.175 | L5: =0.4*N5 -> 0.2 | M5: =0.25*N5 -> 0.125 | N5: 0.5 | O5: =SUM(K5:M5) -> 0.5
A6: Trapping of Microplastics in Halocline and Turbidity Layers of the Semi-enclosed Baltic Sea | B6: TF0012 | C6: W | D6: 24 | E6: 0 | F6: 7.16 | G6: items L-1 | I6: 0 | J6: m | K6: 1.3716 | L6: 3.048 | M6: =3.2004-0.46 -> 2.7404 | N6: 7.16 | O6: =SUM(K6:M6) -> 7.16
A7: Trapping of Microplastics in Halocline and Turbidity Layers of the Semi-enclosed Baltic Sea | B7: TF0012 | C7: W | D7: 24 | E7: 10 | F7: 3.01 | G7: items L-1 | I7: 10 | J7: m | K7: =K6/$N6*$N7 -> 0.57660838 | L7: =L6/$N6*$N7 -> 1.281352 | M7: =M6/$N6*$N7 -> 1.1520397 | N7: 3.01 | O7: =SUM(K7:M7) -> 3.01
A8: Trapping of Microplastics in Halocline and Turbidity Layers of the Semi-enclosed Baltic Sea | B8: TF0012 | C8: B | D8: 24 | E8: 24 | F8: 3.9 | G8: items L-1 | I8: 24 | J8: m | K8: =K7/$N7*$N8 -> 0.74710056 | L8: =L7/$N7*$N8 -> 1.6602235 | M8: =M7/$N7*$N8 -> 1.492676 | N8: 3.9 | O8: =SUM(K8:M8) -> 3.9
A9: Trapping of Microplastics in Halocline and Turbidity Layers of the Semi-enclosed Baltic Sea | B9: TF0012 | C9: S | D9: 24 | E9: 2 - 7cm | F9: 1.5 | G9: items L-1 | I9: =4.5/100 -> 0.045 | J9: m | K9: =0.35*N9 -> 0.525 | L9: =0.4*N9 -> 0.6 | M9: =0.25*N9 -> 0.375 | N9: 1.5 | O9: =SUM(K9:M9) -> 1.5
A10: Trapping of Microplastics in Halocline and Turbidity Layers of the Semi-enclosed Baltic Sea | B10: TF0360 | C10: W | D10: 17 | E10: 0 | F10: 4.83 | G10: items L-1 | I10: 0 | J10: m | K10: =0.18*N10 -> 0.8694 | L10: =0.4*N10 -> 1.932 | M10: =0.42*N10 -> 2.0286 | N10: 4.83 | O10: =SUM(K10:M10) -> 4.83
A11: Trapping of Microplastics in Halocline and Turbidity Layers of the Semi-enclosed Baltic Sea | B11: TF0360 | C11: W | D11: 17 | E11: 10 | F11: 3.01 | G11: items L-1 | I11: 10 | J11: m | K11: =0.18*N11 -> 0.5418 | L11: =0.4*N11 -> 1.204 | M11: =0.42*N11 -> 1.2642 | N11: 3.01 | O11: =SUM(K11:M11) -> 3.01
A12: Trapping of Microplastics in Halocline and Turbidity Layers of the Semi-enclosed Baltic Sea | B12: TF0360 | C12: B | D12: 17 | E12: 17 | F12: 6.71 | G12: items L-1 | I12: 17 | J12: m | K12: =0.18*N12 -> 1.2078 | L12: =0.4*N12 -> 2.684 | M12: =0.42*N12 -> 2.8182 | N12: 6.71 | O12: =SUM(K12:M12) -> 6.71
A13: Trapping of Microplastics in Halocline and Turbidity Layers of the Semi-enclosed Baltic Sea | B13: TF0360 | C13: S | D13: 17 | E13: 2 - 7cm | F13: 0.4 | G13: items L-1 | I13: =4.5/100 -> 0.045 | J13: m | K13: =0.35*N13 -> 0.14 | L13: =0.4*N13 -> 0.16 | M13: =0.25*N13 -> 0.1 | N13: 0.4 | O13: =SUM(K13:M13) -> 0.4
A14: Trapping of Microplastics in Halocline and Turbidity Layers of the Semi-enclosed Baltic Sea | B14: TF0010 | C14: W | D14: 27 | E14: 0 | F14: 11.85 | G14: items L-1 | I14: 0 | J14: m | K14: =0.18*N14 -> 2.133 | L14: =0.4*N14 -> 4.74 | M14: =0.42*N14 -> 4.977 | N14: 11.85 | O14: =SUM(K14:M14) -> 11.85
A15: Trapping of Microplastics in Halocline and Turbidity Layers of the Semi-enclosed Baltic Sea | B15: TF0010 | C15: W | D15: 27 | E15: 20 | F15: 6.23 | G15: items L-1 | I15: 20 | J15: m | K15: =0.18*N15 -> 0 | L15: =0.4*N15 -> 0 | M15: =0.42*N15 -> 0 | O15: =SUM(K15:M15) -> 0
A16: Trapping of Microplastics in Halocline and Turbidity Layers of the Semi-enclosed Baltic Sea | B16: TF0010 | C16: B | D16: 27 | E16: 27 | F16: 5.22 | G16: items L-1 | I16: 27 | J16: m | K16: =0.18*N16 -> 0.9396 | L16: =0.4*N16 -> 2.088 | M16: =0.42*N16 -> 2.1924 | N16: 5.22 | O16: =SUM(K16:M16) -> 5.22
A17: Trapping of Microplastics in Halocline and Turbidity Layers of the Semi-enclosed Baltic Sea | B17: TF0010 | C17: S | D17: 27 | E17: 2 - 7cm | F17: 0.5 | G17: items L-1 | I17: =4.5/100 -> 0.045 | J17: m | K17: =0.35*N17 -> 0.175 | L17: =0.4*N17 -> 0.2 | M17: =0.25*N17 -> 0.125 | N17: 0.5 | O17: =SUM(K17:M17) -> 0.5
A18: Trapping of Microplastics in Halocline and Turbidity Layers of the Semi-enclosed Baltic Sea | B18: TF0113 | C18: W | D18: 46 | E18: 0 | F18: 6.43 | G18: items L-1 | I18: 0 | J18: m | K18: =0.18*N18 -> 1.1574 | L18: =0.4*N18 -> 2.572 | M18: =0.42*N18 -> 2.7006 | N18: 6.43 | O18: =SUM(K18:M18) -> 6.43
A19: Trapping of Microplastics in Halocline and Turbidity Layers of the Semi-enclosed Baltic Sea | B19: TF0113 | C19: W | D19: 46 | E19: 20 | F19: 9.96 | G19: items L-1 | I19: 20 | J19: m | O19: =SUM(K19:M19) -> 0
A20: Trapping of Microplastics in Halocline and Turbidity Layers of the Semi-enclosed Baltic Sea | B20: TF0113 | C20: B | D20: 46 | E20: 46 | F20: 10.72 | G20: items L-1 | I20: 46 | J20: m | K20: =0.18*N20 -> 1.9296 | L20: =0.4*N20 -> 4.288 | M20: =0.42*N20 -> 4.5024 | N20: 10.72 | O20: =SUM(K20:M20) -> 10.72
A21: Trapping of Microplastics in Halocline and Turbidity Layers of the Semi-enclosed Baltic Sea | B21: TF0113 | C21: S | D21: 46 | E21: 2 - 7cm | F21: 0.7 | G21: items L-1 | I21: =4.5/100 -> 0.045 | J21: m | K21: =0.35*N21 -> 0.245 | L21: =0.4*N21 -> 0.28 | M21: =0.25*N21 -> 0.175 | N21: 0.7 | O21: =SUM(K21:M21) -> 0.7
A22: Trapping of Microplastics in Halocline and Turbidity Layers of the Semi-enclosed Baltic Sea | B22: TF0213 | C22: W | D22: 88 | E22: 0 | F22: 14.77 | G22: items L-1 | I22: 0 | J22: m | K22: =0.18*N22 -> 2.6586 | L22: =0.4*N22 -> 5.908 | M22: =0.42*N22 -> 6.2034 | N22: 14.77 | O22: =SUM(K22:M22) -> 14.77
A23: Trapping of Microplastics in Halocline and Turbidity Layers of the Semi-enclosed Baltic Sea | B23: TF0213 | C23: W | D23: 88 | E23: 20 | F23: 5.84 | G23: items L-1 | I23: 20 | J23: m | K23: =0.18*N23 -> 1.0512 | L23: =0.4*N23 -> 2.336 | M23: =0.42*N23 -> 2.4528 | N23: 5.84 | O23: =SUM(K23:M23) -> 5.84
A24: Trapping of Microplastics in Halocline and Turbidity Layers of the Semi-enclosed Baltic Sea | B24: TF0213 | C24: W | D24: 88 | E24: 50 | F24: 7.48 | G24: items L-1 | I24: 50 | J24: m | K24: =0.18*N24 -> 1.3464 | L24: =0.4*N24 -> 2.992 | M24: =0.42*N24 -> 3.1416 | N24: 7.48 | O24: =SUM(K24:M24) -> 7.48
A25: Trapping of Microplastics in Halocline and Turbidity Layers of the Semi-enclosed Baltic Sea | B25: TF0213 | C25: B | D25: 88 | E25: 88 | F25: 2.91 | G25: items L-1 | I25: 88 | J25: m | K25: =0.18*N25 -> 0.5238 | L25: =0.4*N25 -> 1.164 | M25: =0.42*N25 -> 1.2222 | N25: 2.91 | O25: =SUM(K25:M25) -> 2.91
A26: Trapping of Microplastics in Halocline and Turbidity Layers of the Semi-enclosed Baltic Sea | B26: TF0213 | C26: S | D26: 88 | E26: 2 - 7cm | F26: 0.5 | G26: items L-1 | I26: =4.5/100 -> 0.045 | J26: m | K26: =0.35*N26 -> 0.175 | L26: =0.4*N26 -> 0.2 | M26: =0.25*N26 -> 0.125 | N26: 0.5 | O26: =SUM(K26:M26) -> 0.5
A27: Trapping of Microplastics in Halocline and Turbidity Layers of the Semi-enclosed Baltic Sea | B27: TF0256 | C27: W | D27: 75 | E27: 0 | F27: 3.8 | G27: items L-1 | I27: 0 | J27: m | K27: =0.18*N27 -> 0.684 | L27: =0.4*N27 -> 1.52 | M27: =0.42*N27 -> 1.596 | N27: 3.8 | O27: =SUM(K27:M27) -> 3.8
A28: Trapping of Microplastics in Halocline and Turbidity Layers of the Semi-enclosed Baltic Sea | B28: TF0256 | C28: W | D28: 75 | E28: 20 | F28: 5.3 | G28: items L-1 | I28: 20 | J28: m | K28: =0.18*N28 -> 0.954 | L28: =0.4*N28 -> 2.12 | M28: =0.42*N28 -> 2.226 | N28: 5.3 | O28: =SUM(K28:M28) -> 5.3
A29: Trapping of Microplastics in Halocline and Turbidity Layers of the Semi-enclosed Baltic Sea | B29: TF0256 | C29: W | D29: 75 | E29: 50 | F29: 1.93 | G29: items L-1 | I29: 50 | J29: m | K29: =0.18*N29 -> 0.3474 | L29: =0.4*N29 -> 0.772 | M29: =0.42*N29 -> 0.8106 | N29: 1.93 | O29: =SUM(K29:M29) -> 1.93
A30: Trapping of Microplastics in Halocline and Turbidity Layers of the Semi-enclosed Baltic Sea | B30: TF0256 | C30: B | D30: 75 | E30: 75 | F30: 3.42 | G30: items L-1 | I30: 75 | J30: m | K30: =0.18*N30 -> 0.6156 | L30: =0.4*N30 -> 1.368 | M30: =0.42*N30 -> 1.4364 | N30: 3.42 | O30: =SUM(K30:M30) -> 3.42
A31: Trapping of Microplastics in Halocline and Turbidity Layers of the Semi-enclosed Baltic Sea | B31: TF0256 | C31: S | D31: 75 | E31: 2 - 7cm | F31: 0.9 | G31: items L-1 | I31: =4.5/100 -> 0.045 | J31: m | K31: =0.35*N31 -> 0.315 | L31: =0.4*N31 -> 0.36 | M31: =0.25*N31 -> 0.225 | N31: 0.9 | O31: =SUM(K31:M31) -> 0.9
A32: Trapping of Microplastics in Halocline and Turbidity Layers of the Semi-enclosed Baltic Sea | B32: TF0271 | C32: W | D32: 234 | E32: 0 | F32: 1.02 | G32: items L-1 | I32: 0 | J32: m | K32: =0.18*N32 -> 0.1836 | L32: =0.4*N32 -> 0.408 | M32: =0.42*N32 -> 0.4284 | N32: 1.02 | O32: =SUM(K32:M32) -> 1.02
A33: Trapping of Microplastics in Halocline and Turbidity Layers of the Semi-enclosed Baltic Sea | B33: TF0271 | C33: W | D33: 234 | E33: 20 | F33: 2.9 | G33: items L-1 | I33: 20 | J33: m | K33: =0.18*N33 -> 0.522 | L33: =0.4*N33 -> 1.16 | M33: =0.42*N33 -> 1.218 | N33: 2.9 | O33: =SUM(K33:M33) -> 2.9
A34: Trapping of Microplastics in Halocline and Turbidity Layers of the Semi-enclosed Baltic Sea | B34: TF0271 | C34: W | D34: 234 | E34: 50 | F34: 4.59 | G34: items L-1 | I34: 50 | J34: m | K34: =0.18*N34 -> 0.8262 | L34: =0.4*N34 -> 1.836 | M34: =0.42*N34 -> 1.9278 | N34: 4.59 | O34: =SUM(K34:M34) -> 4.59
A35: Trapping of Microplastics in Halocline and Turbidity Layers of the Semi-enclosed Baltic Sea | B35: TF0271 | C35: W | D35: 234 | E35: 100 | F35: 4.23 | G35: items L-1 | I35: 100 | J35: m | K35: =0.18*N35 -> 0.7614 | L35: =0.4*N35 -> 1.692 | M35: =0.42*N35 -> 1.7766 | N35: 4.23 | O35: =SUM(K35:M35) -> 4.23
A36: Trapping of Microplastics in Halocline and Turbidity Layers of the Semi-enclosed Baltic Sea | B36: TF0271 | C36: W | D36: 234 | E36: 200 | F36: 3 | G36: items L-1 | I36: 200 | J36: m | K36: =0.18*N36 -> 0.54 | L36: =0.4*N36 -> 1.2 | M36: =0.42*N36 -> 1.26 | N36: 3 | O36: =SUM(K36:M36) -> 3
A37: Trapping of Microplastics in Halocline and Turbidity Layers of the Semi-enclosed Baltic Sea | B37: TF0271 | C37: B | D37: 234 | E37: 234 | F37: 5.6 | G37: items L-1 | I37: 234 | J37: m | K37: =0.18*N37 -> 1.008 | L37: =0.4*N37 -> 2.24 | M37: =0.42*N37 -> 2.352 | N37: 5.6 | O37: =SUM(K37:M37) -> 5.6
A38: Trapping of Microplastics in Halocline and Turbidity Layers of the Semi-enclosed Baltic Sea | B38: TF0271 | C38: S | D38: 234 | E38: 2 - 7cm | G38: items L-1 | I38: =4.5/100 -> 0.045 | J38: m | O38: =SUM(K38:M38) -> 0
A39: Trapping of Microplastics in Halocline and Turbidity Layers of the Semi-enclosed Baltic Sea | B39: TF0286 | C39: W | D39: 190 | E39: 0 | F39: 21.6 | G39: items L-1 | I39: 0 | J39: m | K39: =0.18*N39 -> 3.888 | L39: =0.4*N39 -> 8.64 | M39: =0.42*N39 -> 9.072 | N39: 21.6 | O39: =SUM(K39:M39) -> 21.6
A40: Trapping of Microplastics in Halocline and Turbidity Layers of the Semi-enclosed Baltic Sea | B40: TF0286 | C40: W | D40: 190 | E40: 20 | F40: 2.64 | G40: items L-1 | I40: 20 | J40: m | K40: =0.18*N40 -> 0.4752 | L40: =0.4*N40 -> 1.056 | M40: =0.42*N40 -> 1.1088 | N40: 2.64 | O40: =SUM(K40:M40) -> 2.64
...
